<?xml version="1.0" ?>
<sdf version="1.6">

    <model name='simple_robot'>
<!--      <pose>0 4.12 0.325 0 -0 0</pose>-->
    <!--     BODY PARTS        -->
        <link name='chassis'>
            <pose>0 0 .15 0 0 0</pose>
            <inertial>
              <mass>30</mass>
              <inertia>
                <ixx>0.005</ixx>
                <ixy>0</ixy>
                <ixz>0</ixz>
                <iyy>0.005</iyy>
                <iyz>0</iyz>
                <izz>0.005</izz>
              </inertia>
            </inertial>
            <visual name='visual'>
              <geometry>
                <sphere>
                    <radius>0.09</radius>
                </sphere>
              </geometry>
              <material>
                <diffuse>1.0 1.0 1.0</diffuse>
                <pbr>
                    <specular>
                        <albedo_map>eye.png</albedo_map>
                        <specular_map>eye.png</specular_map>
                    </specular>
                  </pbr>
              </material>
            </visual>
            <collision name='collision'>
              <geometry>
                <sphere>
                    <radius>0.09</radius>
                </sphere>
              </geometry>
            </collision>
          </link>


    <!--        Wheel section   -->

      <link name='rear_left_wheel'>
        <pose>-0.07 0.088 0.05 0 1.5707 1.5707</pose>
      <inertial>
        <mass>0.408233</mass>
        <inertia>
          <ixx>0.03</ixx>
          <iyy>0.03</iyy>
          <izz>0.03</izz>
          <ixy>0</ixy>
          <ixz>0</ixz>
          <iyz>0</iyz>
        </inertia>
      </inertial>
        <visual name='visual'>
          <geometry>
            <cylinder>
              <radius>0.0325</radius>
              <length>.02</length>
            </cylinder>
          </geometry>
          <material>
            <ambient>0.2 0.2 0.2 1</ambient>
            <diffuse>0.2 0.2 0.2 1</diffuse>
            <specular>0.2 0.2 0.2 1</specular>
                <pbr>
                    <metal>
                        <albedo_map>wheel4.png</albedo_map>
                        <normal_map>wheel4.png</normal_map>
                    </metal>
              </pbr>
          </material>
        </visual>
        <collision name='collision'>
          <geometry>
            <cylinder>
              <radius>0.0325</radius>
              <length>.02</length>
            </cylinder>
          </geometry>
        <surface>
          <friction>
            <dynamic_friction>1.0</dynamic_friction>
            <ode>
              <mu>1.0</mu>
              <mu2>1</mu2>
              <fdir1>1 1 0</fdir1>
              <slip1>0.1</slip1>
              <slip2>0.1</slip2>
            </ode>
          </friction>
          <contact>
            <ode>
              <min_depth>0.005</min_depth>
              <kp>1e7</kp>
            </ode>
          </contact>
        </surface>
        </collision>
      </link>

      <link name='rear_right_wheel'>
        <pose> -0.07 -0.088 0.05 0 1.5707 1.5707 </pose>
      <inertial>
        <mass>0.408233</mass>
        <inertia>
          <ixx>0.03</ixx>
          <iyy>0.03</iyy>
          <izz>0.03</izz>
          <ixy>0</ixy>
          <ixz>0</ixz>
          <iyz>0</iyz>
        </inertia>
      </inertial>
        <visual name='visual'>
          <geometry>
            <cylinder>
              <radius>0.0325</radius>
              <length>.02</length>
            </cylinder>
          </geometry>
          <material>
            <ambient>0.2 0.2 0.2 1</ambient>
            <diffuse>0.2 0.2 0.2 1</diffuse>
            <specular>0.2 0.2 0.2 1</specular>
                <pbr>
                    <metal>
                        <albedo_map>wheel1.png</albedo_map>
                        <normal_map>wheel1.png</normal_map>
                    </metal>
              </pbr>
          </material>
        </visual>
        <collision name='collision'>
          <geometry>
            <cylinder>
              <radius>0.0325</radius>
              <length>.02</length>
            </cylinder>
          </geometry>
        <surface>
          <friction>
            <dynamic_friction>1.0</dynamic_friction>
            <ode>
              <mu>1.0</mu>
              <mu2>1.0</mu2>
              <fdir1>1 1 0</fdir1>
              <slip1>0.1</slip1>
              <slip2>0.1</slip2>
            </ode>
          </friction>
          <contact>
            <ode>
              <min_depth>0.005</min_depth>
              <kp>1e7</kp>
            </ode>
          </contact>
        </surface>
        </collision>
      </link>

      <link name='front_left_wheel'>
        <pose>0.07 0.088 0.05 0 1.5707 1.5707</pose>
      <inertial>
        <mass>0.408233</mass>
        <inertia>
          <ixx>0.03</ixx>
          <iyy>0.03</iyy>
          <izz>0.03</izz>
          <ixy>0</ixy>
          <ixz>0</ixz>
          <iyz>0</iyz>
        </inertia>
      </inertial>
        <visual name='visual'>
          <geometry>
            <cylinder>
              <radius>0.0325</radius>
              <length>.02</length>
            </cylinder>
          </geometry>
          <material>
            <ambient>0.2 0.2 0.2 1</ambient>
            <diffuse>0.2 0.2 0.2 1</diffuse>
            <specular>0.2 0.2 0.2 1</specular>
                <pbr>
                    <metal>
                        <albedo_map>wheel2.png</albedo_map>
                        <normal_map>wheel2.png</normal_map>
                    </metal>
              </pbr>
          </material>
        </visual>
        <collision name='collision'>
          <geometry>
            <cylinder>
              <radius>0.0325</radius>
              <length>.02</length>
            </cylinder>
          </geometry>
        <surface>
          <friction>
            <dynamic_friction>1.0</dynamic_friction>
            <ode>
              <mu>1.0</mu>
              <mu2>1.0</mu2>
              <fdir1>1 1 0</fdir1>
              <slip1>0.1</slip1>
              <slip2>0.1</slip2>
            </ode>
          </friction>
          <contact>
            <ode>
              <min_depth>0.005</min_depth>
              <kp>1e7</kp>
            </ode>
          </contact>
        </surface>
        </collision>
      </link>

      <link name='front_right_wheel'>
        <pose>0.07 -0.088 0.05 0 1.5707 1.5707</pose>
      <inertial>
        <mass>0.408233</mass>
        <inertia>
          <ixx>0.03</ixx>
          <iyy>0.03</iyy>
          <izz>0.03</izz>
          <ixy>0</ixy>
          <ixz>0</ixz>
          <iyz>0</iyz>
        </inertia>
      </inertial>
        <visual name='visual'>
          <geometry>
             <cylinder>
              <radius>0.0325</radius>
              <length>.02</length>
            </cylinder>
          </geometry>
          <material>
            <ambient>0.2 0.2 0.2 1</ambient>
            <diffuse>0.2 0.2 0.2 1</diffuse>
            <specular>0.2 0.2 0.2 1</specular>
                <pbr>
                    <metal>
                        <albedo_map>wheel3.png</albedo_map>
                        <normal_map>wheel3.png</normal_map>
                    </metal>
              </pbr>
          </material>
        </visual>
        <collision name='collision'>
          <geometry>
            <cylinder>
              <radius>0.0325</radius>
              <length>.02</length>
            </cylinder>
          </geometry>
        <surface>
          <friction>
            <dynamic_friction>1.0</dynamic_friction>
            <ode>
              <mu>1.0</mu>
              <mu2>1.0</mu2>
              <fdir1>1 1 0</fdir1>
              <slip1>0.1</slip1>
              <slip2>0.1</slip2>
            </ode>
          </friction>
          <contact>
            <ode>
              <min_depth>0.005</min_depth>
              <kp>1e7</kp>
            </ode>
          </contact>
        </surface>
        </collision>
      </link>


    <!--        Joint section        -->

    <joint name='rear_left_wheel_joint' type='revolute'>
        <parent>chassis</parent>
        <child>rear_left_wheel</child>
        <axis>
          <xyz>0 1 0</xyz>
        <limit>
            <lower>-1.79769e+308</lower>    <!--negative infinity-->
            <upper>1.79769e+308</upper>     <!--positive infinity-->
        </limit>
        <dynamics>
          <damping>1</damping>
          <friction>1</friction>
          <spring_reference>0</spring_reference>
          <spring_stiffness>0</spring_stiffness>
        </dynamics>
        <use_parent_model_frame>1</use_parent_model_frame>
        </axis>
      <physics>
        <ode>
          <implicit_spring_damper>1</implicit_spring_damper>
          <cfm_damping>1</cfm_damping>
          <limit>
            <cfm>0</cfm>
            <erp>0.2</erp>
          </limit>
        </ode>
      </physics>
      </joint>



    <joint name='rear_right_wheel_joint' type='revolute'>
        <parent>chassis</parent>
        <child>rear_right_wheel</child>
        <axis>
          <xyz>0 1 0</xyz>
        <limit>
            <lower>-1.79769e+308</lower>    <!--negative infinity-->
            <upper>1.79769e+308</upper>     <!--positive infinity-->
        </limit>
        <dynamics>
          <damping>1</damping>
          <friction>1</friction>
          <spring_reference>0</spring_reference>
          <spring_stiffness>0</spring_stiffness>
        </dynamics>
        <use_parent_model_frame>1</use_parent_model_frame>
        </axis>
      <physics>
        <ode>
          <implicit_spring_damper>1</implicit_spring_damper>
          <cfm_damping>1</cfm_damping>
          <limit>
            <cfm>0</cfm>
            <erp>0.2</erp>
          </limit>
        </ode>
      </physics>
      </joint>




    <joint name='front_left_wheel_joint' type='revolute'>
        <parent>chassis</parent>
        <child>front_left_wheel</child>
        <axis>
          <xyz>0 1 0</xyz>
        <limit>
            <lower>-1.79769e+308</lower>    <!--negative infinity-->
            <upper>1.79769e+308</upper>     <!--positive infinity-->
        </limit>
        <dynamics>
          <damping>1</damping>
          <friction>1</friction>
          <spring_reference>0</spring_reference>
          <spring_stiffness>0</spring_stiffness>
        </dynamics>
        <use_parent_model_frame>1</use_parent_model_frame>
        </axis>
      <physics>
        <ode>
          <implicit_spring_damper>1</implicit_spring_damper>
          <cfm_damping>1</cfm_damping>
          <limit>
            <cfm>0</cfm>
            <erp>0.2</erp>
          </limit>
        </ode>
      </physics>
      </joint>



    <joint name='front_right_wheel_joint' type='revolute'>
        <parent>chassis</parent>
        <child>front_right_wheel</child>
        <axis>
          <xyz>0 1 0</xyz>
        <limit>
            <lower>-1.79769e+308</lower>    <!--negative infinity-->
            <upper>1.79769e+308</upper>     <!--positive infinity-->
        </limit>
        <dynamics>
          <damping>1</damping>
          <friction>1</friction>
          <spring_reference>0</spring_reference>
          <spring_stiffness>0</spring_stiffness>
        </dynamics>
        <use_parent_model_frame>1</use_parent_model_frame>
        </axis>
      <physics>
        <ode>
          <implicit_spring_damper>1</implicit_spring_damper>
          <cfm_damping>1</cfm_damping>
          <limit>
            <cfm>0</cfm>
            <erp>0.2</erp>
          </limit>
        </ode>
      </physics>
      </joint>

      <plugin
        filename="libignition-gazebo-diff-drive-system.so"
        name="ignition::gazebo::systems::DiffDrive">
        <left_joint>rear_left_wheel_joint</left_joint>
        <left_joint>front_left_wheel_joint</left_joint>
        <right_joint>rear_right_wheel_joint</right_joint>
          <right_joint>front_right_wheel_joint</right_joint>
        <wheel_separation>1.25</wheel_separation>
        <wheel_radius>0.3</wheel_radius>
        <topic>cmd_vel</topic>
      </plugin>

  </model>

</sdf>

